Workbook

Sheet Assumptions
A1: SkyPulse Drone Medical Logistics — Key Assumptions
A2: Blue = input (edit these) · Yellow = key lever · All money in ₹ lakh unless stated · Launch: Karnataka
A4: Parameter | B4: Unit | C4: Y1 FY27-28 | D4: Y2 FY28-29 | E4: Y3 FY29-30 | F4: Y4 FY30-31 | G4: Y5 FY31-32 | H4: Source / Note
A5: Operations
A6: Drone hubs operational | B6: nos | C6: 2 | D6: 4 | E6: 7 | F6: 10 | G6: 14 | H6: Y1: Chikkaballapur & Kolar district hospitals; expand to 14 Karnataka districts by Y5
A7: Drones per hub | B7: nos | C7: 6 | D7: 6 | E7: 6 | F7: 6 | G7: 6 | H7: 4 in rotation + 2 standby/charging per hub
A8: Deliveries per drone per day | B8: nos | C8: 5 | D8: 7 | E8: 8 | F8: 9 | G8: 10 | H8: Ramp-up as hospitals onboard; ~45 min round trip, daylight VLOS/approved corridors
A9: Operating days per year | B9: days | C9: 330 | D9: 330 | E9: 330 | F9: 330 | G9: 330 | H9: Allows ~35 days lost to monsoon/weather & maintenance
A10: Emergency share of deliveries | B10: % | C10: 0.35 | D10: 0.33 | E10: 0.3 | F10: 0.3 | G10: 0.3 | H10: Rwanda (Zipline): ~40% emergency, 60% resupply — Nisingizwe et al., Lancet Glob Health 2022
A11: Pricing & contracts
A12: Emergency delivery fee (blood, anti-venom, drugs) | B12: ₹/delivery | C12: 1400 | D12: 1400 | E12: 1450 | F12: 1500 | G12: 1550 | H12: Below drone cost of ₹3,743/round trip in NE India study (Gupta et al., JFMPC 2025) due to multi-drop routing
A13: Scheduled delivery fee (samples, resupply) | B13: ₹/delivery | C13: 500 | D13: 500 | E13: 525 | F13: 550 | G13: 575 | H13: Benchmarked to ₹150–300 commercial drone parcels + cold-chain premium
A14: Partner hospitals on subscription | B14: nos | C14: 8 | D14: 20 | E14: 40 | F14: 65 | G14: 95 | H14: Private hospitals/diagnostic chains (cf. Narayana Health–Airbound pilot, 2025)
A15: Subscription fee (priority SLA + dashboard) | B15: ₹/month | C15: 25000 | D15: 25000 | E15: 25000 | F15: 25000 | G15: 25000 | H15: Guaranteed <30 min dispatch SLA
A16: Govt. district contracts (NHM / State Health Dept.) | B16: nos | C16: 1 | D16: 2 | E16: 4 | F16: 6 | G16: 8 | H16: Annual service contract per district for PHC resupply
A17: Value per district contract | B17: ₹ lakh/yr | C17: 36 | D17: 36 | E17: 36 | F17: 36 | G17: 36 | H17: ₹3 lakh per month fixed retainer
A18: Variable cost per delivery
A19: Energy / charging | B19: ₹ | C19: 12 | D19: 12 | E19: 12 | F19: 12 | G19: 12 | H19: ~1.2 kWh per sortie at ₹10/kWh incl. losses
A20: Battery wear (amortised) | B20: ₹ | C20: 55 | D20: 55 | E20: 55 | F20: 55 | G20: 55 | H20: Pack ₹55k / ~1,000 cycles
A21: Cold-chain packaging & consumables | B21: ₹ | C21: 70 | D21: 70 | E21: 70 | F21: 70 | G21: 70 | H21: Insulated box, gel packs, tamper seal
A22: Maintenance & spares | B22: ₹ | C22: 85 | D22: 85 | E22: 85 | F22: 85 | G22: 85 | H22: Propellers, motors, periodic overhaul
A23: Telecom, payments & per-flight software | B23: ₹ | C23: 18 | D23: 18 | E23: 18 | F23: 18 | G23: 18 | H23: 4G telemetry, UTM, gateway charges
A24: Fixed operating costs
A25: Remote pilots per hub | B25: nos | C25: 3 | D25: 3 | E25: 3 | F25: 3 | G25: 3 | H25: DGCA Remote Pilot Certificate holders; 2 shifts + relief
A26: Remote pilot salary | B26: ₹ lakh/yr | C26: 5.4 | D26: 5.4 | E26: 5.4 | F26: 5.4 | G26: 5.4 | H26: ₹45,000/month CTC
A27: Drone technicians per hub | B27: nos | C27: 2 | D27: 2 | E27: 2 | F27: 2 | G27: 2
A28: Technician salary | B28: ₹ lakh/yr | C28: 4.2 | D28: 4.2 | E28: 4.2 | F28: 4.2 | G28: 4.2 | H28: ₹35,000/month CTC
A29: Hub managers per hub | B29: nos | C29: 1 | D29: 1 | E29: 1 | F29: 1 | G29: 1
A30: Hub manager salary | B30: ₹ lakh/yr | C30: 8.4 | D30: 8.4 | E30: 8.4 | F30: 8.4 | G30: 8.4 | H30: ₹70,000/month CTC
A31: Hub rent & utilities | B31: ₹ lakh/hub/yr | C31: 6 | D31: 6 | E31: 6 | F31: 6 | G31: 6 | H31: Rooftop/ground pad leased at district hospital
A32: Drone hull & third-party insurance | B32: ₹ lakh/drone/yr | C32: 0.9 | D32: 0.9 | E32: 0.9 | F32: 0.9 | G32: 0.9 | H32: Third-party insurance mandatory under Drone Rules 2021
A33: Corporate team (CEO, CTO, ops, sales, finance) | B33: ₹ lakh/yr | C33: 90 | D33: 120 | E33: 155 | F33: 190 | G33: 230 | H33: See Organisational Plan
A34: Marketing & business development | B34: % of revenue | C34: 0.08 | D34: 0.07 | E34: 0.06 | F34: 0.05 | G34: 0.05 | H34: Hospital demos, CME events, govt. tenders
A35: Regulatory, certification & compliance | B35: ₹ lakh/yr | C35: 15 | D35: 15 | E35: 18 | F35: 20 | G35: 22 | H35: UIN, type certificate, BVLOS approvals, audits
A36: Cloud, UTM & app platform | B36: ₹ lakh/yr | C36: 12 | D36: 18 | E36: 25 | F36: 32 | G36: 40 | H36: Hosting, maps, SMS, security
A37: Capital expenditure
A38: Drone unit cost (5 kg VTOL, cold-chain pod) | B38: ₹ lakh | C38: 14 | D38: 14 | E38: 14 | F38: 14 | G38: 14 | H38: Indian listings ₹3.6–18 lakh; Wingcopter-class ~US$20k; NE study ₹40 lakh incl. insurance
A39: Hub setup (pad, chargers, cold storage, GCS) | B39: ₹ lakh/hub | C39: 22 | D39: 22 | E39: 22 | F39: 22 | G39: 22 | H39: One-time per new hub
A40: Platform development & upgrades | B40: ₹ lakh | C40: 60 | D40: 15 | E40: 15 | F40: 20 | G40: 20 | H40: Ordering app, dispatch engine, hospital dashboard
A41: Asset life for depreciation (straight line) | B41: years | C41: 5 | D41: 5 | E41: 5 | F41: 5 | G41: 5
...

Sheet Revenue
A1: Revenue Build-up
A2: ₹ lakh unless stated · all cells are formulas linked to Assumptions
A4: Particulars | B4: Unit | C4: Y1 FY27-28 | D4: Y2 FY28-29 | E4: Y3 FY29-30 | F4: Y4 FY30-31 | G4: Y5 FY31-32 | H4: Source / Note
A5: Volume
A6: Drone fleet | B6: nos | C6: =Assumptions!C6*Assumptions!C7 | D6: =Assumptions!D6*Assumptions!D7 | E6: =Assumptions!E6*Assumptions!E7 | F6: =Assumptions!F6*Assumptions!F7 | G6: =Assumptions!G6*Assumptions!G7
A7: Total deliveries | B7: nos | C7: =C6*Assumptions!C8*Assumptions!C9 | D7: =D6*Assumptions!D8*Assumptions!D9 | E7: =E6*Assumptions!E8*Assumptions!E9 | F7: =F6*Assumptions!F8*Assumptions!F9 | G7: =G6*Assumptions!G8*Assumptions!G9
A8: Emergency deliveries | B8: nos | C8: =C7*Assumptions!C10 | D8: =D7*Assumptions!D10 | E8: =E7*Assumptions!E10 | F8: =F7*Assumptions!F10 | G8: =G7*Assumptions!G10
A9: Scheduled deliveries | B9: nos | C9: =C7-C8 | D9: =D7-D8 | E9: =E7-E8 | F9: =F7-F8 | G9: =G7-G8
A10: Revenue streams (₹ lakh)
A11: Emergency delivery fees | B11: ₹ lakh | C11: =C8*Assumptions!C12/100000 | D11: =D8*Assumptions!D12/100000 | E11: =E8*Assumptions!E12/100000 | F11: =F8*Assumptions!F12/100000 | G11: =G8*Assumptions!G12/100000
A12: Scheduled delivery fees | B12: ₹ lakh | C12: =C9*Assumptions!C13/100000 | D12: =D9*Assumptions!D13/100000 | E12: =E9*Assumptions!E13/100000 | F12: =F9*Assumptions!F13/100000 | G12: =G9*Assumptions!G13/100000
A13: Hospital subscriptions | B13: ₹ lakh | C13: =Assumptions!C14*Assumptions!C15*12/100000 | D13: =Assumptions!D14*Assumptions!D15*12/100000 | E13: =Assumptions!E14*Assumptions!E15*12/100000 | F13: =Assumptions!F14*Assumptions!F15*12/100000 | G13: =Assumptions!G14*Assumptions!G15*12/100000
A14: Government district contracts | B14: ₹ lakh | C14: =Assumptions!C16*Assumptions!C17 | D14: =Assumptions!D16*Assumptions!D17 | E14: =Assumptions!E16*Assumptions!E17 | F14: =Assumptions!F16*Assumptions!F17 | G14: =Assumptions!G16*Assumptions!G17
A15: Total revenue | B15: ₹ lakh | C15: =SUM(C11:C14) | D15: =SUM(D11:D14) | E15: =SUM(E11:E14) | F15: =SUM(F11:F14) | G15: =SUM(G11:G14)
A16: Revenue growth | B16: % | C16: 0 | D16: =IF(C15=0,0,D15/C15-1) | E16: =IF(D15=0,0,E15/D15-1) | F16: =IF(E15=0,0,F15/E15-1) | G16: =IF(F15=0,0,G15/F15-1) | H16: Y1 = launch year
A17: Avg. revenue per delivery (fees only) | B17: ₹ | C17: =IF(C7=0,0,(C11+C12)*100000/C7) | D17: =IF(D7=0,0,(D11+D12)*100000/D7) | E17: =IF(E7=0,0,(E11+E12)*100000/E7) | F17: =IF(F7=0,0,(F11+F12)*100000/F7) | G17: =IF(G7=0,0,(G11+G12)*100000/G7)

Sheet Costs & Capex
A1: Operating Costs and Capital Expenditure
A2: ₹ lakh unless stated
A4: Particulars | B4: Unit | C4: Y1 FY27-28 | D4: Y2 FY28-29 | E4: Y3 FY29-30 | F4: Y4 FY30-31 | G4: Y5 FY31-32 | H4: Source / Note
A5: Variable costs
A6: Variable cost per delivery | B6: ₹ | C6: =SUM(Assumptions!C19,Assumptions!C20,Assumptions!C21,Assumptions!C22,Assumptions!C23) | D6: =SUM(Assumptions!D19,Assumptions!D20,Assumptions!D21,Assumptions!D22,Assumptions!D23) | E6: =SUM(Assumptions!E19,Assumptions!E20,Assumptions!E21,Assumptions!E22,Assumptions!E23) | F6: =SUM(Assumptions!F19,Assumptions!F20,Assumptions!F21,Assumptions!F22,Assumptions!F23) | G6: =SUM(Assumptions!G19,Assumptions!G20,Assumptions!G21,Assumptions!G22,Assumptions!G23)
A7: Total variable cost | B7: ₹ lakh | C7: =Revenue!C7*C6/100000 | D7: =Revenue!D7*D6/100000 | E7: =Revenue!E7*E6/100000 | F7: =Revenue!F7*F6/100000 | G7: =Revenue!G7*G6/100000
A8: Fixed operating costs
A9: Hub staff (pilots, technicians, managers) | B9: ₹ lakh | C9: =Assumptions!C6*(Assumptions!C25*Assumptions!C26+Assumptions!C27*Assumptions!C28+Assumptions!C29*Assumptions!C30) | D9: =Assumptions!D6*(Assumptions!D25*Assumptions!D26+Assumptions!D27*Assumptions!D28+Assumptions!D29*Assumptions!D30) | E9: =Assumptions!E6*(Assumptions!E25*Assumptions!E26+Assumptions!E27*Assumptions!E28+Assumptions!E29*Assumptions!E30) | F9: =Assumptions!F6*(Assumptions!F25*Assumptions!F26+Assumptions!F27*Assumptions!F28+Assumptions!F29*Assumptions!F30) | G9: =Assumptions!G6*(Assumptions!G25*Assumptions!G26+Assumptions!G27*Assumptions!G28+Assumptions!G29*Assumptions!G30)
A10: Hub rent & utilities | B10: ₹ lakh | C10: =Assumptions!C6*Assumptions!C31 | D10: =Assumptions!D6*Assumptions!D31 | E10: =Assumptions!E6*Assumptions!E31 | F10: =Assumptions!F6*Assumptions!F31 | G10: =Assumptions!G6*Assumptions!G31
A11: Insurance | B11: ₹ lakh | C11: =Revenue!C6*Assumptions!C32 | D11: =Revenue!D6*Assumptions!D32 | E11: =Revenue!E6*Assumptions!E32 | F11: =Revenue!F6*Assumptions!F32 | G11: =Revenue!G6*Assumptions!G32
A12: Corporate team | B12: ₹ lakh | C12: =Assumptions!C33 | D12: =Assumptions!D33 | E12: =Assumptions!E33 | F12: =Assumptions!F33 | G12: =Assumptions!G33
A13: Marketing & business development | B13: ₹ lakh | C13: =Revenue!C15*Assumptions!C34 | D13: =Revenue!D15*Assumptions!D34 | E13: =Revenue!E15*Assumptions!E34 | F13: =Revenue!F15*Assumptions!F34 | G13: =Revenue!G15*Assumptions!G34
A14: Regulatory & compliance | B14: ₹ lakh | C14: =Assumptions!C35 | D14: =Assumptions!D35 | E14: =Assumptions!E35 | F14: =Assumptions!F35 | G14: =Assumptions!G35
A15: Cloud, UTM & app platform | B15: ₹ lakh | C15: =Assumptions!C36 | D15: =Assumptions!D36 | E15: =Assumptions!E36 | F15: =Assumptions!F36 | G15: =Assumptions!G36
A16: Total fixed operating costs | B16: ₹ lakh | C16: =SUM(C9:C15) | D16: =SUM(D9:D15) | E16: =SUM(E9:E15) | F16: =SUM(F9:F15) | G16: =SUM(G9:G15)
A17: Capital expenditure
A18: New drones added | B18: nos | C18: =Revenue!C6 | D18: =Revenue!D6-Revenue!C6 | E18: =Revenue!E6-Revenue!D6 | F18: =Revenue!F6-Revenue!E6 | G18: =Revenue!G6-Revenue!F6
A19: New hubs added | B19: nos | C19: =Assumptions!C6 | D19: =Assumptions!D6-Assumptions!C6 | E19: =Assumptions!E6-Assumptions!D6 | F19: =Assumptions!F6-Assumptions!E6 | G19: =Assumptions!G6-Assumptions!F6
A20: Drone capex | B20: ₹ lakh | C20: =C18*Assumptions!C38 | D20: =D18*Assumptions!D38 | E20: =E18*Assumptions!E38 | F20: =F18*Assumptions!F38 | G20: =G18*Assumptions!G38
A21: Hub setup capex | B21: ₹ lakh | C21: =C19*Assumptions!C39 | D21: =D19*Assumptions!D39 | E21: =E19*Assumptions!E39 | F21: =F19*Assumptions!F39 | G21: =G19*Assumptions!G39
A22: Platform development | B22: ₹ lakh | C22: =Assumptions!C40 | D22: =Assumptions!D40 | E22: =Assumptions!E40 | F22: =Assumptions!F40 | G22: =Assumptions!G40
A23: Total capex | B23: ₹ lakh | C23: =SUM(C20:C22) | D23: =SUM(D20:D22) | E23: =SUM(E20:E22) | F23: =SUM(F20:F22) | G23: =SUM(G20:G22)
A24: Depreciation (straight line) | B24: ₹ lakh | C24: =SUM($C$23:C23)/Assumptions!C41 | D24: =SUM($C$23:D23)/Assumptions!D41 | E24: =SUM($C$23:E23)/Assumptions!E41 | F24: =SUM($C$23:F23)/Assumptions!F41 | G24: =SUM($C$23:G23)/Assumptions!G41 | H24: Cumulative capex ÷ asset life (no asset fully depreciated within 5 years)

Sheet P&L
A1: Projected Profit & Loss Statement
A2: ₹ lakh
A4: Particulars | B4: Unit | C4: Y1 FY27-28 | D4: Y2 FY28-29 | E4: Y3 FY29-30 | F4: Y4 FY30-31 | G4: Y5 FY31-32 | H4: Source / Note
A5: Revenue | B5: ₹ lakh | C5: =Revenue!C15 | D5: =Revenue!D15 | E5: =Revenue!E15 | F5: =Revenue!F15 | G5: =Revenue!G15
A6: Less: variable costs | B6: ₹ lakh | C6: ='Costs & Capex'!C7 | D6: ='Costs & Capex'!D7 | E6: ='Costs & Capex'!E7 | F6: ='Costs & Capex'!F7 | G6: ='Costs & Capex'!G7
A7: Gross profit | B7: ₹ lakh | C7: =C5-C6 | D7: =D5-D6 | E7: =E5-E6 | F7: =F5-F6 | G7: =G5-G6
A8: Gross margin | B8: % | C8: =IF(C5=0,0,C7/C5) | D8: =IF(D5=0,0,D7/D5) | E8: =IF(E5=0,0,E7/E5) | F8: =IF(F5=0,0,F7/F5) | G8: =IF(G5=0,0,G7/G5)
A9: Less: fixed operating costs | B9: ₹ lakh | C9: ='Costs & Capex'!C16 | D9: ='Costs & Capex'!D16 | E9: ='Costs & Capex'!E16 | F9: ='Costs & Capex'!F16 | G9: ='Costs & Capex'!G16
A10: EBITDA | B10: ₹ lakh | C10: =C7-C9 | D10: =D7-D9 | E10: =E7-E9 | F10: =F7-F9 | G10: =G7-G9
A11: EBITDA margin | B11: % | C11: =IF(C5=0,0,C10/C5) | D11: =IF(D5=0,0,D10/D5) | E11: =IF(E5=0,0,E10/E5) | F11: =IF(F5=0,0,F10/F5) | G11: =IF(G5=0,0,G10/G5)
A12: Less: depreciation | B12: ₹ lakh | C12: ='Costs & Capex'!C24 | D12: ='Costs & Capex'!D24 | E12: ='Costs & Capex'!E24 | F12: ='Costs & Capex'!F24 | G12: ='Costs & Capex'!G24
A13: EBIT / Profit before tax | B13: ₹ lakh | C13: =C10-C12 | D13: =D10-D12 | E13: =E10-E12 | F13: =F10-F12 | G13: =G10-G12
A14: Cumulative PBT (for loss set-off) | B14: ₹ lakh | C14: =SUM($C$13:C13) | D14: =SUM($C$13:D13) | E14: =SUM($C$13:E13) | F14: =SUM($C$13:F13) | G14: =SUM($C$13:G13)
A15: Less: tax | B15: ₹ lakh | C15: =MAX(0,MIN(C13,C14))*Assumptions!C43 | D15: =MAX(0,MIN(D13,D14))*Assumptions!D43 | E15: =MAX(0,MIN(E13,E14))*Assumptions!E43 | F15: =MAX(0,MIN(F13,F14))*Assumptions!F43 | G15: =MAX(0,MIN(G13,G14))*Assumptions!G43 | H15: Tax only once cumulative losses are absorbed (carry-forward of losses)
A16: Net profit (PAT) | B16: ₹ lakh | C16: =C13-C15 | D16: =D13-D15 | E16: =E13-E15 | F16: =F13-F15 | G16: =G13-G15
A17: Net margin | B17: % | C17: =IF(C5=0,0,C16/C5) | D17: =IF(D5=0,0,D16/D5) | E17: =IF(E5=0,0,E16/E5) | F17: =IF(F5=0,0,F16/F5) | G17: =IF(G5=0,0,G16/G5)

Sheet Cash Flow
A1: Projected Cash Flow Statement
A2: ₹ lakh
A4: Particulars | B4: Unit | C4: Y1 FY27-28 | D4: Y2 FY28-29 | E4: Y3 FY29-30 | F4: Y4 FY30-31 | G4: Y5 FY31-32 | H4: Source / Note
A5: Opening cash balance | B5: ₹ lakh | C5: 0 | D5: =C13 | E5: =D13 | F5: =E13 | G5: =F13
A6: Net profit (PAT) | B6: ₹ lakh | C6: ='P&L'!C16 | D6: ='P&L'!D16 | E6: ='P&L'!E16 | F6: ='P&L'!F16 | G6: ='P&L'!G16
A7: Add: depreciation | B7: ₹ lakh | C7: ='P&L'!C12 | D7: ='P&L'!D12 | E7: ='P&L'!E12 | F7: ='P&L'!F12 | G7: ='P&L'!G12
A8: Cash flow from operations | B8: ₹ lakh | C8: =C6+C7 | D8: =D6+D7 | E8: =E6+E7 | F8: =F6+F7 | G8: =G6+G7
A9: Less: capex | B9: ₹ lakh | C9: =-'Costs & Capex'!C23 | D9: =-'Costs & Capex'!D23 | E9: =-'Costs & Capex'!E23 | F9: =-'Costs & Capex'!F23 | G9: =-'Costs & Capex'!G23
A10: Funding: founders + grant | B10: ₹ lakh | C10: =Assumptions!C44+Assumptions!C45 | D10: =Assumptions!D44+Assumptions!D45 | E10: =Assumptions!E44+Assumptions!E45 | F10: =Assumptions!F44+Assumptions!F45 | G10: =Assumptions!G44+Assumptions!G45
A11: Funding: equity raised | B11: ₹ lakh | C11: =Assumptions!C46 | D11: =Assumptions!D46 | E11: =Assumptions!E46 | F11: =Assumptions!F46 | G11: =Assumptions!G46
A12: Net change in cash | B12: ₹ lakh | C12: =C8+C9+C10+C11 | D12: =D8+D9+D10+D11 | E12: =E8+E9+E10+E11 | F12: =F8+F9+F10+F11 | G12: =G8+G9+G10+G11
A13: Closing cash balance | B13: ₹ lakh | C13: =C5+C12 | D13: =D5+D12 | E13: =E5+E12 | F13: =F5+F12 | G13: =G5+G12
A14: Cash check (must stay positive) | C14: =IF(C13>=0,"OK","SHORTFALL") | D14: =IF(D13>=0,"OK","SHORTFALL") | E14: =IF(E13>=0,"OK","SHORTFALL") | F14: =IF(F13>=0,"OK","SHORTFALL") | G14: =IF(G13>=0,"OK","SHORTFALL")

Sheet Investment Analysis
A1: Investment Appraisal, Break-even and Unit Economics
A2: ₹ lakh unless stated
A4: Particulars | B4: Unit | C4: Y1 FY27-28 | D4: Y2 FY28-29 | E4: Y3 FY29-30 | F4: Y4 FY30-31 | G4: Y5 FY31-32 | H4: Source / Note
A5: Free cash flow & appraisal
A6: Free cash flow to firm (EBITDA − tax − capex) | B6: ₹ lakh | C6: ='P&L'!C10-'P&L'!C15-'Costs & Capex'!C23 | D6: ='P&L'!D10-'P&L'!D15-'Costs & Capex'!D23 | E6: ='P&L'!E10-'P&L'!E15-'Costs & Capex'!E23 | F6: ='P&L'!F10-'P&L'!F15-'Costs & Capex'!F23 | G6: ='P&L'!G10-'P&L'!G15-'Costs & Capex'!G23
A7: Cumulative free cash flow | B7: ₹ lakh | C7: =SUM($C$6:C6) | D7: =SUM($C$6:D6) | E7: =SUM($C$6:E6) | F7: =SUM($C$6:F6) | G7: =SUM($C$6:G6)
A8: Discount factor | C8: =1/(1+Assumptions!C47)^1 | D8: =1/(1+Assumptions!C47)^2 | E8: =1/(1+Assumptions!C47)^3 | F8: =1/(1+Assumptions!C47)^4 | G8: =1/(1+Assumptions!C47)^5
A9: Discounted free cash flow | B9: ₹ lakh | C9: =C6*C8 | D9: =D6*D8 | E9: =E6*E8 | F9: =F6*F8 | G9: =G6*G8
A10: FCF incl. terminal value (for IRR) | B10: ₹ lakh | C10: =C6 | D10: =D6 | E10: =E6 | F10: =F6 | G10: =G6*6 | H10: Y5 = FCF + terminal value of 5× FCF
A11: NPV of 5-year FCF @ discount rate | C11: =SUM(C9:G9)
A12: Terminal value (Y5 FCF × 5, discounted) | C12: =G6*5*G8 | H12: Exit multiple of 5× FCF — conservative for logistics-tech
A13: Enterprise value (NPV + terminal) | C13: =C11+C12
A14: IRR (5-year FCF + terminal value) | C14: =IRR(C10:G10)
A15: Payback year (cumulative FCF turns positive) | C15: =IF(C7>0,C4,IF(D7>0,D4,IF(E7>0,E4,IF(F7>0,F4,IF(G7>0,G4,"Beyond Y5")))))
A17: Break-even analysis
A18: Contribution per delivery (avg fee − variable cost) | B18: ₹ | C18: =Revenue!C17-'Costs & Capex'!C6 | D18: =Revenue!D17-'Costs & Capex'!D6 | E18: =Revenue!E17-'Costs & Capex'!E6 | F18: =Revenue!F17-'Costs & Capex'!F6 | G18: =Revenue!G17-'Costs & Capex'!G6
A19: Fixed costs + depreciation − contract revenue | B19: ₹ lakh | C19: ='Costs & Capex'!C16+'Costs & Capex'!C24-Revenue!C13-Revenue!C14 | D19: ='Costs & Capex'!D16+'Costs & Capex'!D24-Revenue!D13-Revenue!D14 | E19: ='Costs & Capex'!E16+'Costs & Capex'!E24-Revenue!E13-Revenue!E14 | F19: ='Costs & Capex'!F16+'Costs & Capex'!F24-Revenue!F13-Revenue!F14 | G19: ='Costs & Capex'!G16+'Costs & Capex'!G24-Revenue!G13-Revenue!G14
A20: Break-even deliveries per year | B20: nos | C20: =IF(C18<=0,0,C19*100000/C18) | D20: =IF(D18<=0,0,D19*100000/D18) | E20: =IF(E18<=0,0,E19*100000/E18) | F20: =IF(F18<=0,0,F19*100000/F18) | G20: =IF(G18<=0,0,G19*100000/G18)
A21: Actual deliveries | B21: nos | C21: =Revenue!C7 | D21: =Revenue!D7 | E21: =Revenue!E7 | F21: =Revenue!F7 | G21: =Revenue!G7
A22: Margin of safety | B22: % | C22: =IF(C21=0,0,(C21-C20)/C21) | D22: =IF(D21=0,0,(D21-D20)/D21) | E22: =IF(E21=0,0,(E21-E20)/E21) | F22: =IF(F21=0,0,(F21-F20)/F21) | G22: =IF(G21=0,0,(G21-G20)/G21) | H22: Negative = below break-even that year
A24: Unit economics vs road transport (per emergency delivery)
A25: Fully loaded cost per delivery | B25: ₹ | C25: =('P&L'!C6+'P&L'!C9+'P&L'!C12)*100000/Revenue!C7 | D25: =('P&L'!D6+'P&L'!D9+'P&L'!D12)*100000/Revenue!D7 | E25: =('P&L'!E6+'P&L'!E9+'P&L'!E12)*100000/Revenue!E7 | F25: =('P&L'!F6+'P&L'!F9+'P&L'!F12)*100000/Revenue!F7 | G25: =('P&L'!G6+'P&L'!G9+'P&L'!G12)*100000/Revenue!G7 | H25: All costs incl. depreciation ÷ deliveries; falls as fleet utilisation rises
A26: Road round trip cost (benchmark) | B26: ₹ | C26: 2902 | D26: 2902 | E26: 2902 | F26: 2902 | G26: 2902 | H26: Gupta et al., J Family Med Prim Care 2025 (Meghalaya hub–PHC, 49 km)
A27: Road round trip time (benchmark) | B27: min | C27: 240 | D27: 240 | E27: 240 | F27: 240 | G27: 240 | H27: Same study
A28: Drone round trip time (benchmark) | B28: min | C28: 50 | D28: 50 | E28: 50 | F28: 50 | G28: 50 | H28: Same study
A29: Time saved per delivery | B29: min | C29: =C27-C28 | D29: =D27-D28 | E29: =E27-E28 | F29: =F27-F28 | G29: =G27-G28

Sheet Balance Sheet
A1: Pro Forma Balance Sheet (end of year)
A2: ₹ lakh
A4: Particulars | B4: Unit | C4: Y1 FY27-28 | D4: Y2 FY28-29 | E4: Y3 FY29-30 | F4: Y4 FY30-31 | G4: Y5 FY31-32 | H4: Source / Note
A5: Assets
A6: Cash & bank | B6: ₹ lakh | C6: ='Cash Flow'!C13 | D6: ='Cash Flow'!D13 | E6: ='Cash Flow'!E13 | F6: ='Cash Flow'!F13 | G6: ='Cash Flow'!G13
A7: Gross fixed assets (drones, hubs, platform) | B7: ₹ lakh | C7: =SUM('Costs & Capex'!$C$23:C23) | D7: =SUM('Costs & Capex'!$C$23:D23) | E7: =SUM('Costs & Capex'!$C$23:E23) | F7: =SUM('Costs & Capex'!$C$23:F23) | G7: =SUM('Costs & Capex'!$C$23:G23)
A8: Less: accumulated depreciation | B8: ₹ lakh | C8: =SUM('Costs & Capex'!$C$24:C24) | D8: =SUM('Costs & Capex'!$C$24:D24) | E8: =SUM('Costs & Capex'!$C$24:E24) | F8: =SUM('Costs & Capex'!$C$24:F24) | G8: =SUM('Costs & Capex'!$C$24:G24)
A9: Net fixed assets | B9: ₹ lakh | C9: =C7-C8 | D9: =D7-D8 | E9: =E7-E8 | F9: =F7-F8 | G9: =G7-G8
A10: Total assets | B10: ₹ lakh | C10: =C6+C9 | D10: =D6+D9 | E10: =E6+E9 | F10: =F6+F9 | G10: =G6+G9
A11: Equity & liabilities
A12: Share capital (founders + investors) | B12: ₹ lakh | C12: =SUM(Assumptions!$C$44:C44)+SUM(Assumptions!$C$46:C46) | D12: =SUM(Assumptions!$C$44:D44)+SUM(Assumptions!$C$46:D46) | E12: =SUM(Assumptions!$C$44:E44)+SUM(Assumptions!$C$46:E46) | F12: =SUM(Assumptions!$C$44:F44)+SUM(Assumptions!$C$46:F46) | G12: =SUM(Assumptions!$C$44:G44)+SUM(Assumptions!$C$46:G46)
A13: Capital reserve (SISFS grant) | B13: ₹ lakh | C13: =SUM(Assumptions!$C$45:C45) | D13: =SUM(Assumptions!$C$45:D45) | E13: =SUM(Assumptions!$C$45:E45) | F13: =SUM(Assumptions!$C$45:F45) | G13: =SUM(Assumptions!$C$45:G45)
A14: Retained earnings / (accumulated losses) | B14: ₹ lakh | C14: =SUM('P&L'!$C$16:C16) | D14: =SUM('P&L'!$C$16:D16) | E14: =SUM('P&L'!$C$16:E16) | F14: =SUM('P&L'!$C$16:F16) | G14: =SUM('P&L'!$C$16:G16)
A15: Total equity & liabilities | B15: ₹ lakh | C15: =SUM(C12:C14) | D15: =SUM(D12:D14) | E15: =SUM(E12:E14) | F15: =SUM(F12:F14) | G15: =SUM(G12:G14)
A16: Balance check | C16: =IF(ABS(C10-C15)<0.01,"BALANCED","ERROR") | D16: =IF(ABS(D10-D15)<0.01,"BALANCED","ERROR") | E16: =IF(ABS(E10-E15)<0.01,"BALANCED","ERROR") | F16: =IF(ABS(F10-F15)<0.01,"BALANCED","ERROR") | G16: =IF(ABS(G10-G15)<0.01,"BALANCED","ERROR")

Sheet Sources & Uses
A1: Sources and Applications of Funds (Launch phase: Y1 + Y2)
A2: ₹ lakh
A4: Item | B4: ₹ lakh | C4: Share
A5: Sources
A6: Founders' capital | B6: =SUM(Assumptions!C44:D44) | C6: =B6/$B$10
A7: Startup India Seed Fund grant | B7: =SUM(Assumptions!C45:D45) | C7: =B7/$B$10
A8: Seed round (Y1) | B8: =Assumptions!C46 | C8: =B8/$B$10
A9: Pre-Series A round (Y2) | B9: =Assumptions!D46 | C9: =B9/$B$10
A10: Total sources | B10: =SUM(B6:B9)
A11: Applications
A12: Drones (fleet of 24) | B12: =SUM('Costs & Capex'!C20:D20) | C12: =B12/$B$17
A13: Hub setup (4 hubs) | B13: =SUM('Costs & Capex'!C21:D21) | C13: =B13/$B$17
A14: Technology platform | B14: =SUM('Costs & Capex'!C22:D22) | C14: =B14/$B$17
A15: Less: net operating cash generated (Y1 loss, Y2 profit) | B15: =-SUM('P&L'!C10:D10) | C15: =B15/$B$17
A16: Reserve for Y3 expansion to 7 hubs | B16: ='Cash Flow'!D13 | C16: =B16/$B$17
A17: Total applications | B17: =SUM(B12:B16)
A18: Check (sources = applications) | B18: =IF(ABS(B10-B17)<0.01,"OK","ERROR")

Sheet Sources
A1: Sources used for assumptions
A3: 1. Gupta P, Bhatia R, Choudhury RK, Kotwal A. Leveraging drone technology in health systems strengthening: a cost-effectiveness analysis from Northeast India. J Family Med Prim Care 2025;14(11):4712-21. https://pmc.ncbi.nlm.nih.gov/articles/PMC12704948/
A4: 2. Nisingizwe MP et al. Effect of unmanned aerial vehicle (drone) delivery on blood product delivery time and wastage in Rwanda. Lancet Glob Health 2022. doi:10.1016/S2214-109X(22)00048-1
A5: 3. ICMR i-Drone programme (vaccine, blood and tissue delivery trials incl. Karnataka 2023-24). https://idrone.icmr.org.in/
A6: 4. Ministry of Civil Aviation, Drone Rules 2021 (green zone, UIN, Remote Pilot Certificate, insurance). https://digitalsky.dgca.gov.in/
A7: 5. PLI scheme for drones and drone components, notified 30 Sep 2021, outlay ₹120 crore.
A8: 6. CAG performance audit of 108 Arogya Kavacha ambulance service, Karnataka (30-min rural target met in 72% of cases).
A9: 7. Karnataka snakebite data 2024: 13,235 cases, 100 deaths (Deccan Herald, 2025).
A10: 8. Airbound seed round US$8.65M and Narayana Health contract (TechCrunch / DroneLife, Oct 2025); US$37M raise (TechCrunch, Aug 2026).
A11: 9. MarketsandMarkets: India drone market USD 0.47 bn (2025) → USD 1.39 bn (2030), CAGR 24.4%.
A12: 10. Grand View Research: India delivery drones market USD 22.9 mn (2023) → USD 397.8 mn (2030), CAGR 50.4%.
A13: 11. Mordor Intelligence: global medical drones USD 0.43 bn (2025) → USD 1.18 bn (2030), CAGR 22.19%.
A14: 12. TradeIndia vendor listings: 5 kg payload drone ₹3.6 lakh; 5 kg VTOL fixed-wing ₹18 lakh.
